# Translations template for networking-powervm.
# Copyright (C) 2016 IBM Corp.
# This file is distributed under the same license as the networking-powervm
# project.
# Automatically generated, 2016.
#
msgid ""
msgstr ""
"Project-Id-Version: networking-powervm 3.0.0.0rc2.dev4\n"
"Report-Msgid-Bugs-To: EMAIL@ADDRESS\n"
"POT-Creation-Date: 2016-10-07 02:04-0400\n"
"PO-Revision-Date: 2016-10-07 02:04-0400\n"
"Last-Translator: Automatically generated\n"
"Language-Team: none\n"
"MIME-Version: 1.0\n"
"Content-Type: text/plain; charset=UTF-8\n"
"Content-Transfer-Encoding: 8bit\n"
"Generated-By: Babel 2.3.4\n"

#: networking_powervm/plugins/ibm/agent/powervm/agent_base.py:190
#, python-format
msgid "Unable to parse URI %s for provision request assessment."
msgstr "Не удалось проанализировать URI %s для оценки запроса на выделение ресурсов."

#: networking_powervm/plugins/ibm/agent/powervm/agent_base.py:348
#, python-format
msgid "Sending device DOWN to Neutron for %(dev)s"
msgstr "Отправка устройства в Neutron для %(dev)s"

#: networking_powervm/plugins/ibm/agent/powervm/agent_base.py:556
msgid "Error has been encountered and logged.  The agent will retry again."
msgstr "Произошла ошибка. Сведения о ней занесены в протокол. Агент повторит операцию."

#: networking_powervm/plugins/ibm/agent/powervm/sea_agent.py:203
#, python-format
msgid "Cleaning up VLAN %(vlan)s from the system. It is no longer in use."
msgstr "Удаление VLAN %(vlan)s из системы. Она больше не используется."

#: networking_powervm/plugins/ibm/agent/powervm/sea_agent.py:216
#, python-format
msgid ""
"System identified that VLAN %(vlan)s is unused. However three VLAN clean ups "
"have already occurred in this pass. Will clean up in next optimization pass."
msgstr ""
"Система определила, что VLAN %(vlan)s не используется. Однако в этом сеансе уже "
"была выполнена очистка трех VLAN. Эта очистка отложена до следующего сеанса оптимизации."

#: networking_powervm/plugins/ibm/agent/powervm/sea_agent.py:273
#, python-format
msgid ""
"Unable to determine the Network Bridge (Shared Ethernet Adapter) for "
"physical network %s.  Will be unable to determine appropriate provisioning "
"action."
msgstr ""
"Не удается определить сетевой мост (общий адаптер Ethernet) для "
"физической сети %s.  Невозможно выбрать правильное действие "
"для предоставления ресурсов."

#: networking_powervm/plugins/ibm/agent/powervm/sriov_agent.py:156
#, python-format
msgid "Timed out looking for vNIC with MAC %s.  Not setting device_up."
msgstr "Тайм-аут при поиске vNIC с MAC-адресом %s.  Значение device_up не задано."

#: networking_powervm/plugins/ibm/agent/powervm/utils.py:142
msgid ""
"The bridge_mappings for the agent was not specified.  There was exactly one "
"Network Bridge on the system.  Agent is assuming the default network is "
"backed by the single Network Bridge."
msgstr ""
"Для агента не настроены параметры bridge_mappings. В системе есть "
"ровно один сетевой мост. Агент предполагает, что сеть по умолчанию "
"работает через единственный сетевой мост."

#: networking_powervm/plugins/ibm/agent/powervm/utils.py:327
msgid "No NetworkBridges detected on the host."
msgstr "На хосте не обнаружено ни одного сетевого моста."

# ENGL1SH_VERS10N 43250_4 DO NOT REMOVE OR CHANGE THIS LINE
# T9N_SRC_ID 37
# T9N_SH1P_STR1NG PV132AAP001 2
