# Translations template for networking-powervm.
# Copyright (C) 2016 IBM Corp.
# This file is distributed under the same license as the networking-powervm
# project.
# Automatically generated, 2016.
#
msgid ""
msgstr ""
"Project-Id-Version: networking-powervm 3.0.0.0rc2.dev4\n"
"Report-Msgid-Bugs-To: EMAIL@ADDRESS\n"
"POT-Creation-Date: 2016-10-07 02:04-0400\n"
"PO-Revision-Date: 2016-10-07 02:04-0400\n"
"Last-Translator: Automatically generated\n"
"Language-Team: none\n"
"MIME-Version: 1.0\n"
"Content-Type: text/plain; charset=UTF-8\n"
"Content-Transfer-Encoding: 8bit\n"
"Generated-By: Babel 2.3.4\n"

#: networking_powervm/plugins/ibm/agent/powervm/agent_base.py:190
#, python-format
msgid "Unable to parse URI %s for provision request assessment."
msgstr "No se puede analizar el URI %s para la evaluación de solicitud de provisión."

#: networking_powervm/plugins/ibm/agent/powervm/agent_base.py:348
#, python-format
msgid "Sending device DOWN to Neutron for %(dev)s"
msgstr "Enviando dispositivo DOWN a Neutron para %(dev)s"

#: networking_powervm/plugins/ibm/agent/powervm/agent_base.py:556
msgid "Error has been encountered and logged.  The agent will retry again."
msgstr "Se ha encontrado y registrado un error. El agente volverá a intentarlo."

#: networking_powervm/plugins/ibm/agent/powervm/sea_agent.py:203
#, python-format
msgid "Cleaning up VLAN %(vlan)s from the system. It is no longer in use."
msgstr "Se está limpiando la VLAN %(vlan)s del sistema. Ya no se utiliza."

#: networking_powervm/plugins/ibm/agent/powervm/sea_agent.py:216
#, python-format
msgid ""
"System identified that VLAN %(vlan)s is unused. However three VLAN clean ups "
"have already occurred in this pass. Will clean up in next optimization pass."
msgstr ""
"El sistema ha identificado que la %(vlan)s no se utiliza. Sin embargo, ya se han producido "
"tres limpiezas de la VLAN en este paso. Se producirá otra limpieza en el próximo paso de optimización."

#: networking_powervm/plugins/ibm/agent/powervm/sea_agent.py:273
#, python-format
msgid ""
"Unable to determine the Network Bridge (Shared Ethernet Adapter) for "
"physical network %s.  Will be unable to determine appropriate provisioning "
"action."
msgstr ""
"No se puede determinar el puente de red (adaptador Ethernet compartido) para "
"la red física %s.  No se podrá determinar la acción de suministro "
"apropiada."

#: networking_powervm/plugins/ibm/agent/powervm/sriov_agent.py:156
#, python-format
msgid "Timed out looking for vNIC with MAC %s.  Not setting device_up."
msgstr "Se ha sobrepasado el tiempo de espera buscando vNIC con MAC %s.  No hay ningún valor device_up."

#: networking_powervm/plugins/ibm/agent/powervm/utils.py:142
msgid ""
"The bridge_mappings for the agent was not specified.  There was exactly one "
"Network Bridge on the system.  Agent is assuming the default network is "
"backed by the single Network Bridge."
msgstr ""
"No se ha especificado bridge_mappings para el agente.  Había exactamente un "
"puente de red en el sistema.  El agente presupone que la red predeterminada está "
"respaldada por el puente de red único."

#: networking_powervm/plugins/ibm/agent/powervm/utils.py:327
msgid "No NetworkBridges detected on the host."
msgstr "No se han detectado puentes de red en el host."

# ENGL1SH_VERS10N 43250_4 DO NOT REMOVE OR CHANGE THIS LINE
# T9N_SRC_ID 37
# T9N_SH1P_STR1NG PV132AAP001 2
