# Translations template for networking-powervm.
# Copyright (C) 2016 IBM Corp.
# This file is distributed under the same license as the networking-powervm
# project.
# Automatically generated, 2016.
#
msgid ""
msgstr ""
"Project-Id-Version: networking-powervm 3.0.0.0rc2.dev4\n"
"Report-Msgid-Bugs-To: EMAIL@ADDRESS\n"
"POT-Creation-Date: 2016-10-07 02:04-0400\n"
"PO-Revision-Date: 2016-10-07 02:04-0400\n"
"Last-Translator: Automatically generated\n"
"Language-Team: none\n"
"MIME-Version: 1.0\n"
"Content-Type: text/plain; charset=UTF-8\n"
"Content-Transfer-Encoding: 8bit\n"
"Generated-By: Babel 2.3.4\n"

#: networking_powervm/plugins/ibm/agent/powervm/agent_base.py:190
#, python-format
msgid "Unable to parse URI %s for provision request assessment."
msgstr "Impossibile analizzare l'URI %s per la valutazione della richiesta di provisioning."

#: networking_powervm/plugins/ibm/agent/powervm/agent_base.py:348
#, python-format
msgid "Sending device DOWN to Neutron for %(dev)s"
msgstr "Invio della comunicazione di dispositivo INATTIVO a Neutron per %(dev)s"

#: networking_powervm/plugins/ibm/agent/powervm/agent_base.py:556
msgid "Error has been encountered and logged.  The agent will retry again."
msgstr "È stato rilevato e registrato un errore."

#: networking_powervm/plugins/ibm/agent/powervm/sea_agent.py:203
#, python-format
msgid "Cleaning up VLAN %(vlan)s from the system. It is no longer in use."
msgstr "Cleanup della VLAN %(vlan)s dal sistema. Non è più in uso."

#: networking_powervm/plugins/ibm/agent/powervm/sea_agent.py:216
#, python-format
msgid ""
"System identified that VLAN %(vlan)s is unused. However three VLAN clean ups "
"have already occurred in this pass. Will clean up in next optimization pass."
msgstr ""
"Il sistema ha identificato che la VLAN %(vlan)s non è utilizzata. Tuttavia, tre cleanup di VLAN "
"si sono già verificati in questo passaggio. Il cleanup verrà eseguito nel prossimo passaggio di ottimizzazione."

#: networking_powervm/plugins/ibm/agent/powervm/sea_agent.py:273
#, python-format
msgid ""
"Unable to determine the Network Bridge (Shared Ethernet Adapter) for "
"physical network %s.  Will be unable to determine appropriate provisioning "
"action."
msgstr ""
"Impossibile determinare il bridge di rete (Shared Ethernet Adapter) per "
"la rete fisica %s.  Sarà impossibile determinare l'appropriata azione "
"di provisioning."

#: networking_powervm/plugins/ibm/agent/powervm/sriov_agent.py:156
#, python-format
msgid "Timed out looking for vNIC with MAC %s.  Not setting device_up."
msgstr "Timeout della ricerca di vNIC con MAC %s.  device_up non verrà impostato."

#: networking_powervm/plugins/ibm/agent/powervm/utils.py:142
msgid ""
"The bridge_mappings for the agent was not specified.  There was exactly one "
"Network Bridge on the system.  Agent is assuming the default network is "
"backed by the single Network Bridge."
msgstr ""
"Le associazioni bridge per l'agent non sono state specificate. C'era esattamente un singolo "
"bridge di rete sul sistema. L'agent sta presumendo che la rete predefinita sia "
"supportata dal singolo bridge di rete."

#: networking_powervm/plugins/ibm/agent/powervm/utils.py:327
msgid "No NetworkBridges detected on the host."
msgstr "Nessun bridge di rete rilevato sull'host."

# ENGL1SH_VERS10N 43250_4 DO NOT REMOVE OR CHANGE THIS LINE
# T9N_SRC_ID 37
# T9N_SH1P_STR1NG PV132AAP001 2
